Workbook

Sheet Appraisal Risk Tape
A1: Loan Number | B1: Borrower Name | C1: Loan Purpose | D1: Loan Type | E1: Loan Amount | F1: First Lien Balance | G1: Second Lien Balance | H1: Appraised Value | I1: Contract Price | J1: Purchase Price (Prior) | K1: Purchase Price Date (Prior) | L1: LTV (Calc) | M1: CLTV (Calc) | N1: Occupancy Type | O1: DSCR | P1: Address | Q1: City | R1: County | S1: State | T1: ZIP | U1: Census Tract | V1: Property Type | W1: Units | X1: Year Built | Y1: GLA (SF) | Z1: Basement (SF) | AA1: Lot Size (SF/Acres) | AB1: Beds | AC1: Baths Full | AD1: Baths Half | AE1: Parking/ Garage | AF1: Condition Rating | AG1: Quality Rating | AH1: Effective Age | AI1: Renovation Date | AJ1: Appraisal Effective Date | AK1: Appraiser License | AL1: Form Type | AM1: Reconciliation Notes | AN1: Prior Sale 24M Price | AO1: Prior Sale 24M Date | AP1: 24M Appreciation % (Calc) | AQ1: Prior Sale 36M Price | AR1: Prior Sale 36M Date | AS1: 36M Appreciation % (Calc) | AT1: Market Trend | AU1: Avg DOM | AV1: Months of Inventory | AW1: Number of Comps | AX1: Comp Price Range Low | AY1: Comp Price Range High | AZ1: Avg Price/SF (Comps) | BA1: Avg Distance (mi) | BB1: Max Distance (mi) | BC1: Comps Date Range (Months Back) | BD1: Non-MLS Count | BE1: Non-MLS % (Calc) | BF1: Avg Net Adj % | BG1: Avg Gross Adj % | BH1: High Net/Gross Flag (Auto) | BI1: Chain of Title Red Flags (Y/N) | BJ1: Cash-Out Refi (Y/N) | BK1: AVM Value | BL1: AVM Gap % (Calc) | BM1: High-Risk Geography Flag (Y/N) | BN1: UCDP SSR Score | BO1: Collateral Risk Rating | BP1: Appraiser Geo Competency Flag (Y/N) | BQ1: Unusual Appreciation Flag (Auto) | BR1: DSCR Flag (Auto) | BS1: Non-Public Comps Flag (Auto) | BT1: Overall Decision | BU1: Reviewer Notes
L2: =IFERROR(E2/H2,"") | M2: =IFERROR((F2+G2)/H2,"") | AP2: =IFERROR((H2-AN2)/AN2,"") | AS2: =IFERROR((H2-AQ2)/AQ2,"") | BE2: =IFERROR(BD2/AW2,"") | BH2: =IF(OR(BF2>Thresholds!$B$7,BG2>Thresholds!$B$8),"YES","") | BL2: =IFERROR(ABS(H2-BK2)/BK2,"") | BQ2: =IF(OR(AP2>Thresholds!$B$5,AS2>Thresholds!$B$6),"YES","") -> YES | BS2: =IF(BE2>Thresholds!$B$9,"YES","") -> YES
L3: =IFERROR(E3/H3,"") | M3: =IFERROR((F3+G3)/H3,"") | AP3: =IFERROR((H3-AN3)/AN3,"") | AS3: =IFERROR((H3-AQ3)/AQ3,"") | BE3: =IFERROR(BD3/AW3,"") | BH3: =IF(OR(BF3>Thresholds!$B$7,BG3>Thresholds!$B$8),"YES","") | BL3: =IFERROR(ABS(H3-BK3)/BK3,"") | BQ3: =IF(OR(AP3>Thresholds!$B$5,AS3>Thresholds!$B$6),"YES","") -> YES | BS3: =IF(BE3>Thresholds!$B$9,"YES","") -> YES
L4: =IFERROR(E4/H4,"") | M4: =IFERROR((F4+G4)/H4,"") | AP4: =IFERROR((H4-AN4)/AN4,"") | AS4: =IFERROR((H4-AQ4)/AQ4,"") | BE4: =IFERROR(BD4/AW4,"") | BH4: =IF(OR(BF4>Thresholds!$B$7,BG4>Thresholds!$B$8),"YES","") | BL4: =IFERROR(ABS(H4-BK4)/BK4,"") | BQ4: =IF(OR(AP4>Thresholds!$B$5,AS4>Thresholds!$B$6),"YES","") -> YES | BS4: =IF(BE4>Thresholds!$B$9,"YES","") -> YES
L5: =IFERROR(E5/H5,"") | M5: =IFERROR((F5+G5)/H5,"") | AP5: =IFERROR((H5-AN5)/AN5,"") | AS5: =IFERROR((H5-AQ5)/AQ5,"") | BE5: =IFERROR(BD5/AW5,"") | BH5: =IF(OR(BF5>Thresholds!$B$7,BG5>Thresholds!$B$8),"YES","") | BL5: =IFERROR(ABS(H5-BK5)/BK5,"") | BQ5: =IF(OR(AP5>Thresholds!$B$5,AS5>Thresholds!$B$6),"YES","") -> YES | BS5: =IF(BE5>Thresholds!$B$9,"YES","") -> YES
L6: =IFERROR(E6/H6,"") | M6: =IFERROR((F6+G6)/H6,"") | AP6: =IFERROR((H6-AN6)/AN6,"") | AS6: =IFERROR((H6-AQ6)/AQ6,"") | BE6: =IFERROR(BD6/AW6,"") | BH6: =IF(OR(BF6>Thresholds!$B$7,BG6>Thresholds!$B$8),"YES","") | BL6: =IFERROR(ABS(H6-BK6)/BK6,"") | BQ6: =IF(OR(AP6>Thresholds!$B$5,AS6>Thresholds!$B$6),"YES","") -> YES | BS6: =IF(BE6>Thresholds!$B$9,"YES","") -> YES
L7: =IFERROR(E7/H7,"") | M7: =IFERROR((F7+G7)/H7,"") | AP7: =IFERROR((H7-AN7)/AN7,"") | AS7: =IFERROR((H7-AQ7)/AQ7,"") | BE7: =IFERROR(BD7/AW7,"") | BH7: =IF(OR(BF7>Thresholds!$B$7,BG7>Thresholds!$B$8),"YES","") | BL7: =IFERROR(ABS(H7-BK7)/BK7,"") | BQ7: =IF(OR(AP7>Thresholds!$B$5,AS7>Thresholds!$B$6),"YES","") -> YES | BS7: =IF(BE7>Thresholds!$B$9,"YES","") -> YES
L8: =IFERROR(E8/H8,"") | M8: =IFERROR((F8+G8)/H8,"") | AP8: =IFERROR((H8-AN8)/AN8,"") | AS8: =IFERROR((H8-AQ8)/AQ8,"") | BE8: =IFERROR(BD8/AW8,"") | BH8: =IF(OR(BF8>Thresholds!$B$7,BG8>Thresholds!$B$8),"YES","") | BL8: =IFERROR(ABS(H8-BK8)/BK8,"") | BQ8: =IF(OR(AP8>Thresholds!$B$5,AS8>Thresholds!$B$6),"YES","") -> YES | BS8: =IF(BE8>Thresholds!$B$9,"YES","") -> YES
L9: =IFERROR(E9/H9,"") | M9: =IFERROR((F9+G9)/H9,"") | AP9: =IFERROR((H9-AN9)/AN9,"") | AS9: =IFERROR((H9-AQ9)/AQ9,"") | BE9: =IFERROR(BD9/AW9,"") | BH9: =IF(OR(BF9>Thresholds!$B$7,BG9>Thresholds!$B$8),"YES","") | BL9: =IFERROR(ABS(H9-BK9)/BK9,"") | BQ9: =IF(OR(AP9>Thresholds!$B$5,AS9>Thresholds!$B$6),"YES","") -> YES | BS9: =IF(BE9>Thresholds!$B$9,"YES","") -> YES
L10: =IFERROR(E10/H10,"") | M10: =IFERROR((F10+G10)/H10,"") | AP10: =IFERROR((H10-AN10)/AN10,"") | AS10: =IFERROR((H10-AQ10)/AQ10,"") | BE10: =IFERROR(BD10/AW10,"") | BH10: =IF(OR(BF10>Thresholds!$B$7,BG10>Thresholds!$B$8),"YES","") | BL10: =IFERROR(ABS(H10-BK10)/BK10,"") | BQ10: =IF(OR(AP10>Thresholds!$B$5,AS10>Thresholds!$B$6),"YES","") -> YES | BS10: =IF(BE10>Thresholds!$B$9,"YES","") -> YES
L11: =IFERROR(E11/H11,"") | M11: =IFERROR((F11+G11)/H11,"") | AP11: =IFERROR((H11-AN11)/AN11,"") | AS11: =IFERROR((H11-AQ11)/AQ11,"") | BE11: =IFERROR(BD11/AW11,"") | BH11: =IF(OR(BF11>Thresholds!$B$7,BG11>Thresholds!$B$8),"YES","") | BL11: =IFERROR(ABS(H11-BK11)/BK11,"") | BQ11: =IF(OR(AP11>Thresholds!$B$5,AS11>Thresholds!$B$6),"YES","") -> YES | BS11: =IF(BE11>Thresholds!$B$9,"YES","") -> YES
L12: =IFERROR(E12/H12,"") | M12: =IFERROR((F12+G12)/H12,"") | AP12: =IFERROR((H12-AN12)/AN12,"") | AS12: =IFERROR((H12-AQ12)/AQ12,"") | BE12: =IFERROR(BD12/AW12,"") | BH12: =IF(OR(BF12>Thresholds!$B$7,BG12>Thresholds!$B$8),"YES","") | BL12: =IFERROR(ABS(H12-BK12)/BK12,"") | BQ12: =IF(OR(AP12>Thresholds!$B$5,AS12>Thresholds!$B$6),"YES","") -> YES | BS12: =IF(BE12>Thresholds!$B$9,"YES","") -> YES
L13: =IFERROR(E13/H13,"") | M13: =IFERROR((F13+G13)/H13,"") | AP13: =IFERROR((H13-AN13)/AN13,"") | AS13: =IFERROR((H13-AQ13)/AQ13,"") | BE13: =IFERROR(BD13/AW13,"") | BH13: =IF(OR(BF13>Thresholds!$B$7,BG13>Thresholds!$B$8),"YES","") | BL13: =IFERROR(ABS(H13-BK13)/BK13,"") | BQ13: =IF(OR(AP13>Thresholds!$B$5,AS13>Thresholds!$B$6),"YES","") -> YES | BS13: =IF(BE13>Thresholds!$B$9,"YES","") -> YES
... L1001: =IFERROR(E1001/H1001,"") | M1001: =IFERROR((F1001+G1001)/H1001,"") | AP1001: =IFERROR((H1001-AN1001)/AN1001,"") | AS1001: =IFERROR((H1001-AQ1001)/AQ1001,"") | BE1001: =IFERROR(BD1001/AW1001,"") | BH1001: =IF(OR(BF1001>Thresholds!$B$7,BG1001>Thresholds!$B$8),"YES","") | BL1001: =IFERROR(ABS(H1001-BK1001)/BK1001,"") | BQ1001: =IF(OR(AP1001>Thresholds!$B$5,AS1001>Thresholds!$B$6),"YES","") -> YES | BS1001: =IF(BE1001>Thresholds!$B$9,"YES","") -> YES

Sheet Output
A1: Loan Number | B1: Borrower Name | C1: Loan Purpose | D1: Loan Type | E1: Loan Amount | F1: First Lien Balance | G1: Second Lien Balance | H1: Appraised Value | I1: Contract Price | J1: Purchase Price (Prior) | K1: Purchase Price Date (Prior) | L1: LTV (Calc) | M1: CLTV (Calc) | N1: Occupancy Type | O1: DSCR | P1: Address | Q1: City | R1: County | S1: State | T1: ZIP | U1: Census Tract | V1: Property Type | W1: Units | X1: Year Built | Y1: GLA (SF) | Z1: Basement (SF) | AA1: Lot Size (SF/Acres) | AB1: Beds | AC1: Baths Full | AD1: Baths Half | AE1: Parking/Garage | AF1: Condition Rating | AG1: Quality Rating | AH1: Effective Age | AI1: Renovation Date | AJ1: Appraisal Effective Date | AK1: Appraiser License | AL1: Form Type | AM1: Reconciliation Notes | AN1: Prior Sale 24M Price | AO1: Prior Sale 24M Date | AP1: 24M Appreciation % (Calc) | AQ1: Prior Sale 36M Price | AR1: Prior Sale 36M Date | AS1: 36M Appreciation % (Calc) | AT1: Market Trend | AU1: Avg DOM | AV1: Months of Inventory | AW1: Number of Comps | AX1: Comp Price Range Low | AY1: Comp Price Range High | AZ1: Avg Price/SF (Comps) | BA1: Avg Distance (mi) | BB1: Max Distance (mi) | BC1: Comps Date Range (Months Back) | BD1: Avg Distance (mi) | BE1: Max Distance (mi) | BF1: Comps Date Range (Months Back) | BG1: Non-MLS Count | BH1: Non-MLS % (Calc) | BI1: Avg Net Adj % | BJ1: Avg Gross Adj % | BK1: High Net/Gross Flag (Auto) | BL1: Chain of Title Red Flags (Y/N) | BM1: Cash-Out Refi (Y/N) | BN1: AVM Value | BO1: AVM Gap % (Calc) | BP1: High-Risk Geography Flag (Y/N) | BQ1: UCDP SSR Score | BR1: Collateral Risk Rating | BS1: Appraiser Geo Competency Flag (Y/N)
A2: Not explicitly provided in the appraisal data. | B2: Walter David & Kimberlv Ann Middleton | C2: Purchase Transaction | D2: Conventional | E2: 615000 | F2: Not explicitly provided in the appraisal data. | G2: Not explicitly provided in the appraisal data. | H2: 617000 | I2: 615000 | J2: 0 | K2: 44407 | L2: 0.996 | M2: Not explicitly provided in the appraisal data. | N2: Owner | O2: Not explicitly provided in the appraisal data. | P2: SR41 Lake Cherokee | Q2: Henderson | R2: Rusk | S2: TX | T2: 75652 | U2: 9501.02 | V2: One-Unit Housing | W2: One | X2: 1990 | Y2: 1,859 square feet | Z2: 0 square feet | AA2: 0.689 acres | AB2: 3 | AC2: 2 | AD2: 0 | AE2: 2-car garage | AF2: Good | AG2: Good | AH2: 10 years | AI2: Recent updates, exact date not specified | AJ2: 45449 | AK2: Not explicitly provided in the appraisal data. | AL2: Uniform Appraisal Report (1004) | AM2: Indicated Value by Sales Comparison Approach: $617,000 | AN2: Not available | AO2: Not available | AP2: Not applicable | AQ2: 0 | AR2: 44407 | AS2: Not applicable | AT2: Stable | AU2: Not explicitly provided in the appraisal data. | AV2: Not explicitly provided in the appraisal data. | AW2: 3 | AX2: 524000 | AY2: 705000 | AZ2: $330.82 to $497.18 per square foot | BA2: 1.92 miles | BB2: 3.09 miles | BC2: square foot | BD2: 1.92 miles | BE2: 3.09 miles | BF2: 12 months | BG2: Not explicitly provided in the appraisal data. | BH2: Not explicitly provided in the appraisal data. | BI2: 0.116 | BJ2: 0.239 | BK2: Exceeds threshold | BL2: Yes | BM2: No | BN2: Not explicitly provided in the appraisal data. | BO2: Not applicable | BP2: No | BQ2: Not explicitly provided in the appraisal data. | BR2: Not explicitly provided in the appraisal data. | BS2: Yes

Sheet Thresholds
A1: Description | B1: Value
A2: LTV threshold | B2: 0.8
A3: CLTV threshold | B3: 0.9
A4: DSCR minimum | B4: 1
A5: 24M Appreciation % threshold | B5: 0.25
A6: 36M Appreciation % threshold | B6: 0.35
A7: Net Adjustment % threshold | B7: 0.15
A8: Gross Adjustment % threshold | B8: 0.25
A9: Non-MLS % threshold | B9: 0.2
A10: AVM Gap % threshold | B10: 0.1

Sheet scratchpad
A1: Loan Number | D1: Loan Number | E1: Not explicitly provided in the appraisal data.
A2: Borrower Name | D2: Borrower Name | E2: Walter David & Kimberlv Ann Middleton
A3: Loan Purpose | D3: Loan Purpose | E3: Purchase Transaction
A4: Loan Type | D4: Loan Type | E4: Conventional
A5: Loan Amount | D5: Loan Amount | E5: 615000
A6: First Lien Balance | D6: First Lien Balance | E6: Not explicitly provided in the appraisal data.
A7: Second Lien Balance | D7: Second Lien Balance | E7: Not explicitly provided in the appraisal data.
A8: Appraised Value | D8: Appraised Value | E8: 617000
A9: Contract Price | D9: Contract Price | E9: 615000
A10: Purchase Price (Prior) | D10: Purchase Price (Prior) | E10: 0
A11: Purchase Price Date (Prior) | D11: Purchase Price Date (Prior) | E11: 44407
A12: LTV (Calc) | D12: LTV (Calc) | E12: 0.996
A13: CLTV (Calc) | D13: CLTV (Calc) | E13: Not explicitly provided in the appraisal data.
A14: Occupancy Type | D14: Occupancy Type | E14: Owner
A15: DSCR | D15: DSCR | E15: Not explicitly provided in the appraisal data.
A16: Address | D16: Address | E16: SR41 Lake Cherokee
A17: City | D17: City | E17: Henderson
A18: County | D18: County | E18: Rusk
A19: State | D19: State | E19: TX
A20: ZIP | D20: ZIP | E20: 75652
A21: Census Tract | D21: Census Tract | E21: 9501.02
A22: Property Type | D22: Property Type | E22: One-Unit Housing
A23: Units | D23: Units | E23: One
A24: Year Built | D24: Year Built | E24: 1990
A25: GLA (SF) | D25: GLA (SF) | E25: 1,859 square feet
A26: Basement (SF) | D26: Basement (SF) | E26: 0 square feet
A27: Lot Size (SF/Acres) | D27: Lot Size (SF/Acres) | E27: 0.689 acres
A28: Beds | D28: Beds | E28: 3
A29: Baths Full | D29: Baths Full | E29: 2
A30: Baths Half | D30: Baths Half | E30: 0
A31: Parking/ Garage | D31: Parking/Garage | E31: 2-car garage
A32: Condition Rating | D32: Condition Rating | E32: Good
A33: Quality Rating | D33: Quality Rating | E33: Good
A34: Effective Age | D34: Effective Age | E34: 10 years
A35: Renovation Date | D35: Renovation Date | E35: Recent updates, exact date not specified
A36: Appraisal Effective Date | D36: Appraisal Effective Date | E36: 45449
A37: Appraiser License | D37: Appraiser License | E37: Not explicitly provided in the appraisal data.
A38: Form Type | D38: Form Type | E38: Uniform Appraisal Report (1004)
A39: Reconciliation Notes | D39: Reconciliation Notes | E39: Indicated Value by Sales Comparison Approach: $617,000
A40: Prior Sale 24M Price | D40: Prior Sale 24M Price | E40: Not available
...

Sheet Lists
A1: Purchase
A2: Rate/Term Refi
A3: Cash-Out Refi
A4: Bridge
A5: DSCR
A6: Other
A7: Conventional
A8: Jumbo
A9: Non-QM
A10: DSCR
A11: Bridge
A12: Private Lender
... A33: Declining
